Testing connection to the update server..
================================================================================
Could not stat: https://vystadial.ms.mff.cuni.cz/download/alex/applications/PublicTransportInfoEN/slu/dailogreg.nbl.model.all
--------------------------------------------------------------------------------

2016-01-01--20-54-39.441662-CET  MainProcess : DEBUG      
    
        Error occured.
          Type: <type 'exceptions.KeyboardInterrupt'>
          Value: 
          Traceback:
              File "simulator_hub.py", line 199, in <module>
                shub = SimulatorHub(cfg)
              File "simulator_hub.py", line 41, in __init__
                self.dm = dm_factory(dm_type, cfg)
              File "/home/root-data/thanh_pro/git_clone/alex/alex/components/dm/common.py", line 20, in dm_factory
                dm = DialogueManager(cfg)
              File "/home/root-data/thanh_pro/git_clone/alex/alex/components/dm/base.py", line 167, in __init__
                self.ontology = Ontology(self.cfg['DM']['ontology'])
              File "/home/root-data/thanh_pro/git_clone/alex/alex/components/dm/ontology.py", line 23, in __init__
                self.load(file_name)
              File "/home/root-data/thanh_pro/git_clone/alex/alex/components/dm/ontology.py", line 32, in load
                on_mod = load_as_module(file_name, force=True)
              File "/home/root-data/thanh_pro/git_clone/alex/alex/utils/config.py", line 218, in load_as_module
                mod = import_module(modname)
              File "/usr/lib/python2.7/importlib/__init__.py", line 37, in import_module
                __import__(name)
              File "/home/root-data/thanh_pro/git_clone/alex/alex/applications/PublicTransportInfoEN/data/ontology.py", line 555, in <module>
                load_compatible_values(os.path.join(dirname, CITIES_LOCATIONS_FNAME), 'city', 'state')
              File "/home/root-data/thanh_pro/git_clone/alex/alex/applications/PublicTransportInfoEN/data/ontology.py", line 518, in load_compatible_values
                for line in fh:
              File "/usr/lib/python2.7/codecs.py", line 681, in next
                return self.reader.next()
              File "/usr/lib/python2.7/codecs.py", line 612, in next
                line = self.readline()
              File "/usr/lib/python2.7/codecs.py", line 527, in readline
                data = self.read(readsize, firstline=True)
              File "/usr/lib/python2.7/codecs.py", line 474, in read
                newchars, decodedbytes = self.decode(data, self.errors)
            

